Workbook

Sheet Inventory Baseline
A1: INVENTORY BASELINE
A2: Actual quantities from the supplied, undated monitoring worksheet. Unit prices have not been supplied.
A3: Blue cells: editable inputs | Gray: supplied data / fixed scope | Green text: formulas | Blank: unknown, never a verified zero
A4: 463 units are unreconciled / missing or without reports. This is not evidence that 463 units were physically lost, stolen or recoverable.
A6: No. | B6: Equipment description | C6: Recorded qty. | D6: Need to comply | E6: Missing / no report | F6: Calculated gap | G6: Gap validation | H6: Est. unit price (₱) | I6: Potential exposure (₱) | J6: Reconciliation indicator | K6: Price source / date | L6: Source
A7: 1 | B7: Shovel (Pala, Lapad) | C7: 19 | F7: =IF(ISNUMBER(D7),MAX(D7-C7,0),"") | G7: =IF(D7="","Not supplied",IF(E7="","No reported gap",IF(F7=E7,"Match","Mismatch"))) -> Not supplied | I7: =IF(OR(E7="",H7=""),"Unverified",E7*H7) -> Unverified | J7: =IF(E7="","Gap information not supplied",IF(E7>0,"Physical / record check required","Reported zero; verify")) -> Gap information not supplied | L7: R1/R2
A8: 2 | B8: Shovel (Pala, Bilog) | C8: 23 | D8: 42 | E8: 19 | F8: =IF(ISNUMBER(D8),MAX(D8-C8,0),"") -> 19 | G8: =IF(D8="","Not supplied",IF(E8="","No reported gap",IF(F8=E8,"Match","Mismatch"))) -> Match | I8: =IF(OR(E8="",H8=""),"Unverified",E8*H8) -> Unverified | J8: =IF(E8="","Gap information not supplied",IF(E8>0,"Physical / record check required","Reported zero; verify")) -> Physical / record check required | L8: R1/R2
A9: 3 | B9: Bareta | C9: 13 | F9: =IF(ISNUMBER(D9),MAX(D9-C9,0),"") | G9: =IF(D9="","Not supplied",IF(E9="","No reported gap",IF(F9=E9,"Match","Mismatch"))) -> Not supplied | I9: =IF(OR(E9="",H9=""),"Unverified",E9*H9) -> Unverified | J9: =IF(E9="","Gap information not supplied",IF(E9>0,"Physical / record check required","Reported zero; verify")) -> Gap information not supplied | L9: R1/R2
A10: 4 | B10: Itak | C10: 4 | F10: =IF(ISNUMBER(D10),MAX(D10-C10,0),"") | G10: =IF(D10="","Not supplied",IF(E10="","No reported gap",IF(F10=E10,"Match","Mismatch"))) -> Not supplied | I10: =IF(OR(E10="",H10=""),"Unverified",E10*H10) -> Unverified | J10: =IF(E10="","Gap information not supplied",IF(E10>0,"Physical / record check required","Reported zero; verify")) -> Gap information not supplied | L10: R1/R2
A11: 5 | B11: Piko | C11: 4 | F11: =IF(ISNUMBER(D11),MAX(D11-C11,0),"") | G11: =IF(D11="","Not supplied",IF(E11="","No reported gap",IF(F11=E11,"Match","Mismatch"))) -> Not supplied | I11: =IF(OR(E11="",H11=""),"Unverified",E11*H11) -> Unverified | J11: =IF(E11="","Gap information not supplied",IF(E11>0,"Physical / record check required","Reported zero; verify")) -> Gap information not supplied | L11: R1/R2
A12: 6 | B12: Plastic Drum 200L | C12: 14 | F12: =IF(ISNUMBER(D12),MAX(D12-C12,0),"") | G12: =IF(D12="","Not supplied",IF(E12="","No reported gap",IF(F12=E12,"Match","Mismatch"))) -> Not supplied | I12: =IF(OR(E12="",H12=""),"Unverified",E12*H12) -> Unverified | J12: =IF(E12="","Gap information not supplied",IF(E12>0,"Physical / record check required","Reported zero; verify")) -> Gap information not supplied | L12: R1/R2
A13: 7 | B13: IBC Water Tank 1000L | C13: 5 | F13: =IF(ISNUMBER(D13),MAX(D13-C13,0),"") | G13: =IF(D13="","Not supplied",IF(E13="","No reported gap",IF(F13=E13,"Match","Mismatch"))) -> Not supplied | I13: =IF(OR(E13="",H13=""),"Unverified",E13*H13) -> Unverified | J13: =IF(E13="","Gap information not supplied",IF(E13>0,"Physical / record check required","Reported zero; verify")) -> Gap information not supplied | L13: R1/R2
A14: 8 | B14: Wheel Barrow | C14: 4 | F14: =IF(ISNUMBER(D14),MAX(D14-C14,0),"") | G14: =IF(D14="","Not supplied",IF(E14="","No reported gap",IF(F14=E14,"Match","Mismatch"))) -> Not supplied | I14: =IF(OR(E14="",H14=""),"Unverified",E14*H14) -> Unverified | J14: =IF(E14="","Gap information not supplied",IF(E14>0,"Physical / record check required","Reported zero; verify")) -> Gap information not supplied | L14: R1/R2
A15: 9 | B15: Oxygen Tank | C15: 3 | F15: =IF(ISNUMBER(D15),MAX(D15-C15,0),"") | G15: =IF(D15="","Not supplied",IF(E15="","No reported gap",IF(F15=E15,"Match","Mismatch"))) -> Not supplied | I15: =IF(OR(E15="",H15=""),"Unverified",E15*H15) -> Unverified | J15: =IF(E15="","Gap information not supplied",IF(E15>0,"Physical / record check required","Reported zero; verify")) -> Gap information not supplied | L15: R1/R2
A16: 10 | B16: Gas Tank | C16: 5 | F16: =IF(ISNUMBER(D16),MAX(D16-C16,0),"") | G16: =IF(D16="","Not supplied",IF(E16="","No reported gap",IF(F16=E16,"Match","Mismatch"))) -> Not supplied | I16: =IF(OR(E16="",H16=""),"Unverified",E16*H16) -> Unverified | J16: =IF(E16="","Gap information not supplied",IF(E16>0,"Physical / record check required","Reported zero; verify")) -> Gap information not supplied | L16: R1/R2
A17: 11 | B17: Electric Kettle | C17: 2 | F17: =IF(ISNUMBER(D17),MAX(D17-C17,0),"") | G17: =IF(D17="","Not supplied",IF(E17="","No reported gap",IF(F17=E17,"Match","Mismatch"))) -> Not supplied | I17: =IF(OR(E17="",H17=""),"Unverified",E17*H17) -> Unverified | J17: =IF(E17="","Gap information not supplied",IF(E17>0,"Physical / record check required","Reported zero; verify")) -> Gap information not supplied | L17: R1/R2
A18: 12 | B18: Extension | C18: 10 | F18: =IF(ISNUMBER(D18),MAX(D18-C18,0),"") | G18: =IF(D18="","Not supplied",IF(E18="","No reported gap",IF(F18=E18,"Match","Mismatch"))) -> Not supplied | I18: =IF(OR(E18="",H18=""),"Unverified",E18*H18) -> Unverified | J18: =IF(E18="","Gap information not supplied",IF(E18>0,"Physical / record check required","Reported zero; verify")) -> Gap information not supplied | L18: R1/R2
A19: 13 | B19: Double Burner Stove | C19: 8 | F19: =IF(ISNUMBER(D19),MAX(D19-C19,0),"") | G19: =IF(D19="","Not supplied",IF(E19="","No reported gap",IF(F19=E19,"Match","Mismatch"))) -> Not supplied | I19: =IF(OR(E19="",H19=""),"Unverified",E19*H19) -> Unverified | J19: =IF(E19="","Gap information not supplied",IF(E19>0,"Physical / record check required","Reported zero; verify")) -> Gap information not supplied | L19: R1/R2
A20: 14 | B20: Lababo | C20: 5 | F20: =IF(ISNUMBER(D20),MAX(D20-C20,0),"") | G20: =IF(D20="","Not supplied",IF(E20="","No reported gap",IF(F20=E20,"Match","Mismatch"))) -> Not supplied | I20: =IF(OR(E20="",H20=""),"Unverified",E20*H20) -> Unverified | J20: =IF(E20="","Gap information not supplied",IF(E20>0,"Physical / record check required","Reported zero; verify")) -> Gap information not supplied | L20: R1/R2
... A22: 16 | B22: Garden Hose | C22: 5 | F22: =IF(ISNUMBER(D22),MAX(D22-C22,0),"") | G22: =IF(D22="","Not supplied",IF(E22="","No reported gap",IF(F22=E22,"Match","Mismatch"))) -> Not supplied | I22: =IF(OR(E22="",H22=""),"Unverified",E22*H22) -> Unverified | J22: =IF(E22="","Gap information not supplied",IF(E22>0,"Physical / record check required","Reported zero; verify")) -> Gap information not supplied | L22: R1/R2
A23: 17 | B23: GI Pipes | C23: 225 | D23: 300 | E23: 75 | F23: =IF(ISNUMBER(D23),MAX(D23-C23,0),"") -> 75 | G23: =IF(D23="","Not supplied",IF(E23="","No reported gap",IF(F23=E23,"Match","Mismatch"))) -> Match | I23: =IF(OR(E23="",H23=""),"Unverified",E23*H23) -> Unverified | J23: =IF(E23="","Gap information not supplied",IF(E23>0,"Physical / record check required","Reported zero; verify")) -> Physical / record check required | L23: R1/R2
A24: 18 | B24: Base Jack | C24: 27 | F24: =IF(ISNUMBER(D24),MAX(D24-C24,0),"") | G24: =IF(D24="","Not supplied",IF(E24="","No reported gap",IF(F24=E24,"Match","Mismatch"))) -> Not supplied | I24: =IF(OR(E24="",H24=""),"Unverified",E24*H24) -> Unverified | J24: =IF(E24="","Gap information not supplied",IF(E24>0,"Physical / record check required","Reported zero; verify")) -> Gap information not supplied | L24: R1/R2
A25: 19 | B25: U-Jack | C25: 56 | F25: =IF(ISNUMBER(D25),MAX(D25-C25,0),"") | G25: =IF(D25="","Not supplied",IF(E25="","No reported gap",IF(F25=E25,"Match","Mismatch"))) -> Not supplied | I25: =IF(OR(E25="",H25=""),"Unverified",E25*H25) -> Unverified | J25: =IF(E25="","Gap information not supplied",IF(E25>0,"Physical / record check required","Reported zero; verify")) -> Gap information not supplied | L25: R1/R2
A26: 20 | B26: Buckets | C26: 39 | F26: =IF(ISNUMBER(D26),MAX(D26-C26,0),"") | G26: =IF(D26="","Not supplied",IF(E26="","No reported gap",IF(F26=E26,"Match","Mismatch"))) -> Not supplied | I26: =IF(OR(E26="",H26=""),"Unverified",E26*H26) -> Unverified | J26: =IF(E26="","Gap information not supplied",IF(E26>0,"Physical / record check required","Reported zero; verify")) -> Gap information not supplied | L26: R1/R2
A27: 21 | B27: Catwalk Platform Scaffolding | C27: 33 | F27: =IF(ISNUMBER(D27),MAX(D27-C27,0),"") | G27: =IF(D27="","Not supplied",IF(E27="","No reported gap",IF(F27=E27,"Match","Mismatch"))) -> Not supplied | I27: =IF(OR(E27="",H27=""),"Unverified",E27*H27) -> Unverified | J27: =IF(E27="","Gap information not supplied",IF(E27>0,"Physical / record check required","Reported zero; verify")) -> Gap information not supplied | L27: R1/R2
A28: 22 | B28: H-Frame Scaffolding | C28: 64 | F28: =IF(ISNUMBER(D28),MAX(D28-C28,0),"") | G28: =IF(D28="","Not supplied",IF(E28="","No reported gap",IF(F28=E28,"Match","Mismatch"))) -> Not supplied | I28: =IF(OR(E28="",H28=""),"Unverified",E28*H28) -> Unverified | J28: =IF(E28="","Gap information not supplied",IF(E28>0,"Physical / record check required","Reported zero; verify")) -> Gap information not supplied | L28: R1/R2
A29: 23 | B29: Braces Scaffolding | C29: 41 | F29: =IF(ISNUMBER(D29),MAX(D29-C29,0),"") | G29: =IF(D29="","Not supplied",IF(E29="","No reported gap",IF(F29=E29,"Match","Mismatch"))) -> Not supplied | I29: =IF(OR(E29="",H29=""),"Unverified",E29*H29) -> Unverified | J29: =IF(E29="","Gap information not supplied",IF(E29>0,"Physical / record check required","Reported zero; verify")) -> Gap information not supplied | L29: R1/R2
A30: 24 | B30: Water Pump | C30: 2 | F30: =IF(ISNUMBER(D30),MAX(D30-C30,0),"") | G30: =IF(D30="","Not supplied",IF(E30="","No reported gap",IF(F30=E30,"Match","Mismatch"))) -> Not supplied | I30: =IF(OR(E30="",H30=""),"Unverified",E30*H30) -> Unverified | J30: =IF(E30="","Gap information not supplied",IF(E30>0,"Physical / record check required","Reported zero; verify")) -> Gap information not supplied | L30: R1/R2
A31: 25 | B31: Garden Sprinkler | C31: 2 | F31: =IF(ISNUMBER(D31),MAX(D31-C31,0),"") | G31: =IF(D31="","Not supplied",IF(E31="","No reported gap",IF(F31=E31,"Match","Mismatch"))) -> Not supplied | I31: =IF(OR(E31="",H31=""),"Unverified",E31*H31) -> Unverified | J31: =IF(E31="","Gap information not supplied",IF(E31>0,"Physical / record check required","Reported zero; verify")) -> Gap information not supplied | L31: R1/R2
A32: 26 | B32: Swivel Clamp | C32: 141 | D32: 510 | E32: 369 | F32: =IF(ISNUMBER(D32),MAX(D32-C32,0),"") -> 369 | G32: =IF(D32="","Not supplied",IF(E32="","No reported gap",IF(F32=E32,"Match","Mismatch"))) -> Match | I32: =IF(OR(E32="",H32=""),"Unverified",E32*H32) -> Unverified | J32: =IF(E32="","Gap information not supplied",IF(E32>0,"Physical / record check required","Reported zero; verify")) -> Physical / record check required | L32: R1/R2
B34: TOTAL / PROVIDED CELLS ONLY | C34: =SUM(C7:C32) -> 758 | D34: =SUM(D7:D32) -> 852 | E34: =SUM(E7:E32) -> 463 | I34: =IF(COUNT(I7:I32)=COUNT(E7:E32),SUM(I7:I32),"Unverified") -> Unverified
A35: Need-to-comply total covers only 3 categories (852 units); it is not an all-inventory requirement. Reported gaps cover only those 3 categories. Prices value exposure only; they do not create annual benefits.
B38: FLAGGED CATEGORIES | C38: Recorded | D38: Requirement | E38: Reported gap | F38: Gap share | I38: Exposure (₱)
B39: =B8 -> Shovel (Pala, Bilog) | C39: =C8 -> 23 | D39: =D8 -> 42 | E39: =E8 -> 19 | F39: =E8/$E$34 -> 0.041036717 | I39: =I8 -> Unverified
B40: =B23 -> GI Pipes | C40: =C23 -> 225 | D40: =D23 -> 300 | E40: =E23 -> 75 | F40: =E23/$E$34 -> 0.16198704 | I40: =I23 -> Unverified
B41: =B32 -> Swivel Clamp | C41: =C32 -> 141 | D41: =D32 -> 510 | E41: =E32 -> 369 | F41: =E32/$E$34 -> 0.79697624 | I41: =I32 -> Unverified
A43: Reconciliation method: confirm description and unit; count at each site; inspect issue/return/transfer records; identify the holder; classify unresolved, found, in transit or confirmed loss; approve corrections with evidence.
A45: Do not add the 463 gaps to recorded stock as a confirmed company total. Different equipment units are counted as recorded units, not equivalent economic assets. Blank cells remain unknown.

Sheet One-Time Development Cost
A1: BREAKDOWN OF ONE TIME COST WORKSHEET
A2: Rates and effort are unverified. Full development valuation; distinguish already incurred cost from remaining work before investment approval.
A3: Blue cells: editable inputs | Gray: supplied data / fixed scope | Green text: formulas | Blank: unknown, never a verified zero
A4: ="Planning duration (calendar months): "&'Assumptions and References'!B8&". Enter actual allocated person-months below; calendar duration does not determine effort." -> Planning duration (calendar months): 3. Enter actual allocated person-months below; calendar duration does not determine effort.
A5: A. DEVELOPMENT COST
A6: Description | B6: Rate (₱ / unit) | C6: Effort / quantity | D6: Unit | E6: Subtotal (₱) | F6: Treatment | G6: Basis / scope
A7: System Analyst | D7: person-month | E7: =IF(OR(F7="Bundled",F7="Not applicable"),0,IF(AND(OR(F7="Estimated",F7="Confirmed"),COUNT(B7:C7)=2),B7*C7,"Insufficient Data")) -> Insufficient Data | F7: To confirm | G7: Enter allocated person-months; roles may overlap. Do not charge full monthly effort twice.
A8: System Developer / Programmer | D8: person-month | E8: =IF(OR(F8="Bundled",F8="Not applicable"),0,IF(AND(OR(F8="Estimated",F8="Confirmed"),COUNT(B8:C8)=2),B8*C8,"Insufficient Data")) -> Insufficient Data | F8: To confirm | G8: Enter allocated person-months; roles may overlap. Do not charge full monthly effort twice.
A9: Database Development | D9: person-month | E9: =IF(OR(F9="Bundled",F9="Not applicable"),0,IF(AND(OR(F9="Estimated",F9="Confirmed"),COUNT(B9:C9)=2),B9*C9,"Insufficient Data")) -> Insufficient Data | F9: To confirm | G9: Enter allocated person-months; roles may overlap. Do not charge full monthly effort twice.
A10: System Testing and Quality Assurance | D10: person-month | E10: =IF(OR(F10="Bundled",F10="Not applicable"),0,IF(AND(OR(F10="Estimated",F10="Confirmed"),COUNT(B10:C10)=2),B10*C10,"Insufficient Data")) -> Insufficient Data | F10: To confirm | G10: Enter allocated person-months; roles may overlap. Do not charge full monthly effort twice.
A11: Documentation and Implementation | D11: person-month | E11: =IF(OR(F11="Bundled",F11="Not applicable"),0,IF(AND(OR(F11="Estimated",F11="Confirmed"),COUNT(B11:C11)=2),B11*C11,"Insufficient Data")) -> Insufficient Data | F11: To confirm | G11: Enter allocated person-months; roles may overlap. Do not charge full monthly effort twice.
A12: Total development cost | E12: =IF(COUNT(E7,E8,E9,E10,E11)=5,SUM(E7,E8,E9,E10,E11),"Insufficient Data") -> Insufficient Data
A14: B. USER TRAINING
A15: Description | B15: Rate (₱ / unit) | C15: Quantity | D15: Unit | E15: Subtotal (₱) | F15: Treatment | G15: Basis / scope
A16: Training preparation | D16: hour | E16: =IF(OR(F16="Bundled",F16="Not applicable"),0,IF(AND(OR(F16="Estimated",F16="Confirmed"),COUNT(B16:C16)=2),B16*C16,"Insufficient Data")) -> Insufficient Data | F16: To confirm | G16: Separate preparation, orientation and session delivery. Include participant paid time once if incremental.
A17: User orientation | D17: hour | E17: =IF(OR(F17="Bundled",F17="Not applicable"),0,IF(AND(OR(F17="Estimated",F17="Confirmed"),COUNT(B17:C17)=2),B17*C17,"Insufficient Data")) -> Insufficient Data | F17: To confirm | G17: Separate preparation, orientation and session delivery. Include participant paid time once if incremental.
A18: Training materials | D18: kit | E18: =IF(OR(F18="Bundled",F18="Not applicable"),0,IF(AND(OR(F18="Estimated",F18="Confirmed"),COUNT(B18:C18)=2),B18*C18,"Insufficient Data")) -> Insufficient Data | F18: To confirm | G18: Separate preparation, orientation and session delivery. Include participant paid time once if incremental.
A19: Training sessions | D19: session | E19: =IF(OR(F19="Bundled",F19="Not applicable"),0,IF(AND(OR(F19="Estimated",F19="Confirmed"),COUNT(B19:C19)=2),B19*C19,"Insufficient Data")) -> Insufficient Data | F19: To confirm | G19: Separate preparation, orientation and session delivery. Include participant paid time once if incremental.
A20: Total training cost | E20: =IF(COUNT(E16,E17,E18,E19)=4,SUM(E16,E17,E18,E19),"Insufficient Data") -> Insufficient Data
A22: C. ADDITIONAL HARDWARE / SOFTWARE
A23: Description | B23: One-time rate (₱) | C23: Quantity | D23: Unit | E23: Subtotal (₱) | F23: Treatment | G23: Basis / scope
A24: Hosting / deployment setup | C24: 1 | D24: setup / item | E24: =IF(OR(F24="Bundled",F24="Not applicable"),0,IF(AND(OR(F24="Estimated",F24="Confirmed"),COUNT(B24:C24)=2),B24*C24,"Insufficient Data")) -> Insufficient Data | F24: To confirm | G24: Check existing capacity, provider bundles and open-source license terms before adding a charge.
A25: Separate database setup | C25: 1 | D25: setup / item | E25: =IF(OR(F25="Bundled",F25="Not applicable"),0,IF(AND(OR(F25="Estimated",F25="Confirmed"),COUNT(B25:C25)=2),B25*C25,"Insufficient Data")) -> Insufficient Data | F25: To confirm | G25: Check existing capacity, provider bundles and open-source license terms before adding a charge.
A26: Backup storage setup | C26: 1 | D26: setup / item | E26: =IF(OR(F26="Bundled",F26="Not applicable"),0,IF(AND(OR(F26="Estimated",F26="Confirmed"),COUNT(B26:C26)=2),B26*C26,"Insufficient Data")) -> Insufficient Data | F26: To confirm | G26: Check existing capacity, provider bundles and open-source license terms before adding a charge.
A27: Domain / SSL setup | C27: 1 | D27: setup / item | E27: =IF(OR(F27="Bundled",F27="Not applicable"),0,IF(AND(OR(F27="Estimated",F27="Confirmed"),COUNT(B27:C27)=2),B27*C27,"Insufficient Data")) -> Insufficient Data | F27: To confirm | G27: Check existing capacity, provider bundles and open-source license terms before adding a charge.
A28: Additional hardware | C28: 1 | D28: setup / item | E28: =IF(OR(F28="Bundled",F28="Not applicable"),0,IF(AND(OR(F28="Estimated",F28="Confirmed"),COUNT(B28:C28)=2),B28*C28,"Insufficient Data")) -> Insufficient Data | F28: To confirm | G28: Check existing capacity, provider bundles and open-source license terms before adding a charge.
A29: Other necessary licenses | C29: 1 | D29: setup / item | E29: =IF(OR(F29="Bundled",F29="Not applicable"),0,IF(AND(OR(F29="Estimated",F29="Confirmed"),COUNT(B29:C29)=2),B29*C29,"Insufficient Data")) -> Insufficient Data | F29: To confirm | G29: Check existing capacity, provider bundles and open-source license terms before adding a charge.
A30: Total hardware / software cost | E30: =IF(COUNT(E24,E25,E26,E27,E28,E29)=6,SUM(E24,E25,E26,E27,E28,E29),"Insufficient Data") -> Insufficient Data
A33: TOTAL ONE-TIME COST | E33: =IF(COUNT(E12,E20,E30)=3,SUM(E12,E20,E30),"Insufficient Data") -> Insufficient Data
A35: Total = development + user training + additional hardware/software. Mark a separately listed bundled charge as Bundled; cite the bundle in its basis. A free tier or existing device is not presumed sufficient.
A37: ₱178,500 in the teaching photograph belongs to another project and is excluded. Paid effort already incurred must be separated from future cash outlay before making a forward investment decision.

Sheet Recurring Costs
A1: RECURRING SYSTEM COSTS
A2: Annual incremental system expenses. Confirm production usage, shared-service allocation and bundled services.
A3: Blue cells: editable inputs | Gray: supplied data / fixed scope | Green text: formulas | Blank: unknown, never a verified zero
A6: Description | B6: Rate (₱ / event) | C6: Quantity | D6: Events per year | E6: Annual subtotal (₱) | F6: Treatment | G6: Basis / scope
A7: System maintenance | C7: 1 | D7: 12 | E7: =IF(OR(F7="Bundled",F7="Not applicable"),0,IF(AND(OR(F7="Estimated",F7="Confirmed"),COUNT(B7:D7)=3),B7*C7*D7,"Insufficient Data")) -> Insufficient Data | F7: To confirm | G7: Maintenance excludes separately billed support. Count shared charges only at the incremental attributable amount.
A8: Hosting | C8: 1 | D8: 12 | E8: =IF(OR(F8="Bundled",F8="Not applicable"),0,IF(AND(OR(F8="Estimated",F8="Confirmed"),COUNT(B8:D8)=3),B8*C8*D8,"Insufficient Data")) -> Insufficient Data | F8: To confirm | G8: No provider quote or approved allocation supplied. Bundle evidence or no-cost basis required.
A9: Database service charges | C9: 1 | D9: 12 | E9: =IF(OR(F9="Bundled",F9="Not applicable"),0,IF(AND(OR(F9="Estimated",F9="Confirmed"),COUNT(B9:D9)=3),B9*C9*D9,"Insufficient Data")) -> Insufficient Data | F9: To confirm | G9: No provider quote or approved allocation supplied. Bundle evidence or no-cost basis required.
A10: Data backup and storage | C10: 1 | D10: 12 | E10: =IF(OR(F10="Bundled",F10="Not applicable"),0,IF(AND(OR(F10="Estimated",F10="Confirmed"),COUNT(B10:D10)=3),B10*C10*D10,"Insufficient Data")) -> Insufficient Data | F10: To confirm | G10: No provider quote or approved allocation supplied. Bundle evidence or no-cost basis required.
A11: Incremental internet / communication | C11: 1 | D11: 12 | E11: =IF(OR(F11="Bundled",F11="Not applicable"),0,IF(AND(OR(F11="Estimated",F11="Confirmed"),COUNT(B11:D11)=3),B11*C11*D11,"Insufficient Data")) -> Insufficient Data | F11: To confirm | G11: No provider quote or approved allocation supplied. Bundle evidence or no-cost basis required.
A12: Software / domain renewals | C12: 1 | D12: 1 | E12: =IF(OR(F12="Bundled",F12="Not applicable"),0,IF(AND(OR(F12="Estimated",F12="Confirmed"),COUNT(B12:D12)=3),B12*C12*D12,"Insufficient Data")) -> Insufficient Data | F12: To confirm | G12: No provider quote or approved allocation supplied. Bundle evidence or no-cost basis required.
A13: Technical support | C13: 1 | D13: 12 | E13: =IF(OR(F13="Bundled",F13="Not applicable"),0,IF(AND(OR(F13="Estimated",F13="Confirmed"),COUNT(B13:D13)=3),B13*C13*D13,"Insufficient Data")) -> Insufficient Data | F13: To confirm | G13: No provider quote or approved allocation supplied. Bundle evidence or no-cost basis required.
A14: Other recurring costs / scheduler | C14: 1 | D14: 1 | E14: =IF(OR(F14="Bundled",F14="Not applicable"),0,IF(AND(OR(F14="Estimated",F14="Confirmed"),COUNT(B14:D14)=3),B14*C14*D14,"Insufficient Data")) -> Insufficient Data | F14: To confirm | G14: No provider quote or approved allocation supplied. Bundle evidence or no-cost basis required.
A16: TOTAL ANNUAL RECURRING COST | E16: =IF(COUNT(E7,E8,E9,E10,E11,E12,E13,E14)=8,SUM(E7,E8,E9,E10,E11,E12,E13,E14),"Insufficient Data") -> Insufficient Data
A18: Default quantities and billing frequencies are editable modelling conventions, not purchased subscriptions. Database and storage may be bundled with hosting; use Bundled only after confirmation.
A20: Technical support is owned by this sheet. Do not repeat it in Proposed Operating Costs. ₱20,500 in the teaching photograph is not a SiteTrace recurring cost.

Sheet Existing System Operating Costs
A1: EXISTING SYSTEM OPERATING COSTS
A2: Labour is an allocated productivity cost. It is not a payroll saving. Activity timing, staffing and wages have not been measured.
A3: Blue cells: editable inputs | Gray: supplied data / fixed scope | Green text: formulas | Blank: unknown, never a verified zero
A5: A. ACTIVITY LABOUR / CAPACITY
A6: Activity | B6: Hours / person / event | C6: Staff | D6: Events / year | E6: Hourly rate (₱) | F6: Annual person-hours | G6: Allocated labour (₱) | H6: Treatment | I6: Measurement basis
A7: Inventory monitoring / updates | C7: 1 | F7: =IF(H7="Not applicable",0,IF(AND(OR(H7="Estimated",H7="Confirmed"),COUNT(B7:D7)=3),B7*C7*D7,"Insufficient Data")) -> Insufficient Data | G7: =IF(H7="Not applicable",0,IF(COUNT(E7:F7)=2,E7*F7,"Insufficient Data")) -> Insufficient Data | H7: To confirm | I7: Use disjoint tasks and timesheets; avoid overlap between reconciliation and follow-up work.
A8: Manual report preparation | C8: 1 | D8: 52 | F8: =IF(H8="Not applicable",0,IF(AND(OR(H8="Estimated",H8="Confirmed"),COUNT(B8:D8)=3),B8*C8*D8,"Insufficient Data")) -> Insufficient Data | G8: =IF(H8="Not applicable",0,IF(COUNT(E8:F8)=2,E8*F8,"Insufficient Data")) -> Insufficient Data | H8: To confirm | I8: Use disjoint tasks and timesheets; avoid overlap between reconciliation and follow-up work.
A9: Inventory reconciliation | C9: 1 | F9: =IF(H9="Not applicable",0,IF(AND(OR(H9="Estimated",H9="Confirmed"),COUNT(B9:D9)=3),B9*C9*D9,"Insufficient Data")) -> Insufficient Data | G9: =IF(H9="Not applicable",0,IF(COUNT(E9:F9)=2,E9*F9,"Insufficient Data")) -> Insufficient Data | H9: To confirm | I9: Use disjoint tasks and timesheets; avoid overlap between reconciliation and follow-up work.
A10: Equipment accountability follow-ups | C10: 1 | F10: =IF(H10="Not applicable",0,IF(AND(OR(H10="Estimated",H10="Confirmed"),COUNT(B10:D10)=3),B10*C10*D10,"Insufficient Data")) -> Insufficient Data | G10: =IF(H10="Not applicable",0,IF(COUNT(E10:F10)=2,E10*F10,"Insufficient Data")) -> Insufficient Data | H10: To confirm | I10: Use disjoint tasks and timesheets; avoid overlap between reconciliation and follow-up work.
A12: Total annual person-hours | F12: =IF(COUNT(F7,F8,F9,F10)=4,SUM(F7,F8,F9,F10),"Insufficient Data") -> Insufficient Data
A13: Total allocated annual labour | G13: =IF(COUNT(G7,G8,G9,G10)=4,SUM(G7,G8,G9,G10),"Insufficient Data") -> Insufficient Data
A15: B. SUPPLIES AND OTHER CASH OPERATING COSTS
A16: Expense | B16: Rate (₱ / unit) | C16: Quantity / event | D16: Events / year | E16: Annual cost (₱) | F16: Treatment | G16: Cost boundary | H16: Evidence / quote | I16: Notes
A17: Paper | E17: =IF(OR(F17="Bundled",F17="Not applicable"),0,IF(AND(OR(F17="Estimated",F17="Confirmed"),COUNT(B17:D17)=3),B17*C17*D17,"Insufficient Data")) -> Insufficient Data | F17: To confirm | G17: Supplies only | I17: Use incremental cash spending; avoid printing / toner overlap.
A18: Printing / copy service (excludes ink) | E18: =IF(OR(F18="Bundled",F18="Not applicable"),0,IF(AND(OR(F18="Estimated",F18="Confirmed"),COUNT(B18:D18)=3),B18*C18*D18,"Insufficient Data")) -> Insufficient Data | F18: To confirm | G18: Supplies only | I18: Use incremental cash spending; avoid printing / toner overlap.
A19: Ink / toner (excludes copy-service charge) | E19: =IF(OR(F19="Bundled",F19="Not applicable"),0,IF(AND(OR(F19="Estimated",F19="Confirmed"),COUNT(B19:D19)=3),B19*C19*D19,"Insufficient Data")) -> Insufficient Data | F19: To confirm | G19: Supplies only | I19: Use incremental cash spending; avoid printing / toner overlap.
A20: Recordkeeping materials | E20: =IF(OR(F20="Bundled",F20="Not applicable"),0,IF(AND(OR(F20="Estimated",F20="Confirmed"),COUNT(B20:D20)=3),B20*C20*D20,"Insufficient Data")) -> Insufficient Data | F20: To confirm | G20: Supplies only | I20: Use incremental cash spending; avoid printing / toner overlap.
A21: Other office supplies | E21: =IF(OR(F21="Bundled",F21="Not applicable"),0,IF(AND(OR(F21="Estimated",F21="Confirmed"),COUNT(B21:D21)=3),B21*C21*D21,"Insufficient Data")) -> Insufficient Data | F21: To confirm | G21: Supplies only | I21: Use incremental cash spending; avoid printing / toner overlap.
A22: Manual record storage | E22: =IF(OR(F22="Bundled",F22="Not applicable"),0,IF(AND(OR(F22="Estimated",F22="Confirmed"),COUNT(B22:D22)=3),B22*C22*D22,"Insufficient Data")) -> Insufficient Data | F22: To confirm | G22: Direct administration expense | I22: Use incremental cash spending; avoid printing / toner overlap.
A23: Reporting / communication | E23: =IF(OR(F23="Bundled",F23="Not applicable"),0,IF(AND(OR(F23="Estimated",F23="Confirmed"),COUNT(B23:D23)=3),B23*C23*D23,"Insufficient Data")) -> Insufficient Data | F23: To confirm | G23: Direct administration expense | I23: Use incremental cash spending; avoid printing / toner overlap.
A24: Other attributable admin cash costs | E24: =IF(OR(F24="Bundled",F24="Not applicable"),0,IF(AND(OR(F24="Estimated",F24="Confirmed"),COUNT(B24:D24)=3),B24*C24*D24,"Insufficient Data")) -> Insufficient Data | F24: To confirm | G24: Direct administration expense | I24: Use incremental cash spending; avoid printing / toner overlap.
A26: Total annual supplies | E26: =IF(COUNT(E17,E18,E19,E20,E21)=5,SUM(E17,E18,E19,E20,E21),"Insufficient Data") -> Insufficient Data
A27: Other annual admin cash costs | E27: =IF(COUNT(E22,E23,E24)=3,SUM(E22,E23,E24),"Insufficient Data") -> Insufficient Data
A28: Annual admin cash cost | E28: =IF(COUNT(E26,E27)=2,SUM(E26,E27),"Insufficient Data") -> Insufficient Data
A30: C. COST VIEW AND FINANCIAL BOUNDARY
A31: Admin cash + allocated labour | E31: =IF(COUNT(E28,G13)=2,SUM(E28,G13),"Insufficient Data") -> Insufficient Data
A33: Historical confirmed loss / replacement cost | F33: Not supplied. Informational only; no loss savings inferred.
A35: No company salaries, historical loss records, paperwork budgets or timing studies were supplied. The worksheet image supports quantities, not a measured labour workflow. Weekly report frequency of 52 follows R12 as a planning convention.
A38: Treatments: Estimated / Confirmed need numeric inputs; Bundled / Not applicable equal an explicit zero; To confirm remains Insufficient Data. Record the supporting basis. Enter zero only after confirming it.

Sheet Proposed System Operating Costs
A1: PROPOSED SYSTEM OPERATING COSTS
A2: Labour is an allocated productivity cost. It is not a payroll saving. Activity timing, staffing and wages have not been measured.
A3: Blue cells: editable inputs | Gray: supplied data / fixed scope | Green text: formulas | Blank: unknown, never a verified zero
A5: A. ACTIVITY LABOUR / CAPACITY
A6: Activity | B6: Hours / person / event | C6: Staff | D6: Events / year | E6: Hourly rate (₱) | F6: Annual person-hours | G6: Allocated labour (₱) | H6: Treatment | I6: Measurement basis
A7: Inventory monitoring / updates | C7: 1 | D7: =IF(ISNUMBER('Existing System Operating Costs'!D7),'Existing System Operating Costs'!D7,"") | E7: =IF(ISNUMBER('Existing System Operating Costs'!E7),'Existing System Operating Costs'!E7,"") | F7: =IF(H7="Not applicable",0,IF(AND(OR(H7="Estimated",H7="Confirmed"),COUNT(B7:D7)=3),B7*C7*D7,"Insufficient Data")) -> Insufficient Data | G7: =IF(H7="Not applicable",0,IF(COUNT(E7:F7)=2,E7*F7,"Insufficient Data")) -> Insufficient Data | H7: To confirm | I7: Include data entry, inspections and any residual manual checks. Same annual workload and wage basis as baseline.
A8: Manual report preparation | C8: 1 | D8: =IF(ISNUMBER('Existing System Operating Costs'!D8),'Existing System Operating Costs'!D8,"") -> 52 | E8: =IF(ISNUMBER('Existing System Operating Costs'!E8),'Existing System Operating Costs'!E8,"") | F8: =IF(H8="Not applicable",0,IF(AND(OR(H8="Estimated",H8="Confirmed"),COUNT(B8:D8)=3),B8*C8*D8,"Insufficient Data")) -> Insufficient Data | G8: =IF(H8="Not applicable",0,IF(COUNT(E8:F8)=2,E8*F8,"Insufficient Data")) -> Insufficient Data | H8: To confirm | I8: Include data entry, inspections and any residual manual checks. Same annual workload and wage basis as baseline.
A9: Inventory reconciliation | C9: 1 | D9: =IF(ISNUMBER('Existing System Operating Costs'!D9),'Existing System Operating Costs'!D9,"") | E9: =IF(ISNUMBER('Existing System Operating Costs'!E9),'Existing System Operating Costs'!E9,"") | F9: =IF(H9="Not applicable",0,IF(AND(OR(H9="Estimated",H9="Confirmed"),COUNT(B9:D9)=3),B9*C9*D9,"Insufficient Data")) -> Insufficient Data | G9: =IF(H9="Not applicable",0,IF(COUNT(E9:F9)=2,E9*F9,"Insufficient Data")) -> Insufficient Data | H9: To confirm | I9: Include data entry, inspections and any residual manual checks. Same annual workload and wage basis as baseline.
A10: Equipment accountability follow-ups | C10: 1 | D10: =IF(ISNUMBER('Existing System Operating Costs'!D10),'Existing System Operating Costs'!D10,"") | E10: =IF(ISNUMBER('Existing System Operating Costs'!E10),'Existing System Operating Costs'!E10,"") | F10: =IF(H10="Not applicable",0,IF(AND(OR(H10="Estimated",H10="Confirmed"),COUNT(B10:D10)=3),B10*C10*D10,"Insufficient Data")) -> Insufficient Data | G10: =IF(H10="Not applicable",0,IF(COUNT(E10:F10)=2,E10*F10,"Insufficient Data")) -> Insufficient Data | H10: To confirm | I10: Include data entry, inspections and any residual manual checks. Same annual workload and wage basis as baseline.
A12: Total annual person-hours | F12: =IF(COUNT(F7,F8,F9,F10)=4,SUM(F7,F8,F9,F10),"Insufficient Data") -> Insufficient Data
A13: Total allocated annual labour | G13: =IF(COUNT(G7,G8,G9,G10)=4,SUM(G7,G8,G9,G10),"Insufficient Data") -> Insufficient Data
A15: B. SUPPLIES AND OTHER CASH OPERATING COSTS
A16: Expense | B16: Rate (₱ / unit) | C16: Quantity / event | D16: Events / year | E16: Annual cost (₱) | F16: Treatment | G16: Cost boundary | H16: Evidence / quote | I16: Notes
A17: Paper | E17: =IF(OR(F17="Bundled",F17="Not applicable"),0,IF(AND(OR(F17="Estimated",F17="Confirmed"),COUNT(B17:D17)=3),B17*C17*D17,"Insufficient Data")) -> Insufficient Data | F17: To confirm | G17: Supplies only | I17: Use incremental cash spending; avoid printing / toner overlap.
A18: Printing / copy service (excludes ink) | E18: =IF(OR(F18="Bundled",F18="Not applicable"),0,IF(AND(OR(F18="Estimated",F18="Confirmed"),COUNT(B18:D18)=3),B18*C18*D18,"Insufficient Data")) -> Insufficient Data | F18: To confirm | G18: Supplies only | I18: Use incremental cash spending; avoid printing / toner overlap.
A19: Ink / toner (excludes copy-service charge) | E19: =IF(OR(F19="Bundled",F19="Not applicable"),0,IF(AND(OR(F19="Estimated",F19="Confirmed"),COUNT(B19:D19)=3),B19*C19*D19,"Insufficient Data")) -> Insufficient Data | F19: To confirm | G19: Supplies only | I19: Use incremental cash spending; avoid printing / toner overlap.
A20: Recordkeeping materials | E20: =IF(OR(F20="Bundled",F20="Not applicable"),0,IF(AND(OR(F20="Estimated",F20="Confirmed"),COUNT(B20:D20)=3),B20*C20*D20,"Insufficient Data")) -> Insufficient Data | F20: To confirm | G20: Supplies only | I20: Use incremental cash spending; avoid printing / toner overlap.
A21: Other office supplies | E21: =IF(OR(F21="Bundled",F21="Not applicable"),0,IF(AND(OR(F21="Estimated",F21="Confirmed"),COUNT(B21:D21)=3),B21*C21*D21,"Insufficient Data")) -> Insufficient Data | F21: To confirm | G21: Supplies only | I21: Use incremental cash spending; avoid printing / toner overlap.
A22: Manual record storage | E22: =IF(OR(F22="Bundled",F22="Not applicable"),0,IF(AND(OR(F22="Estimated",F22="Confirmed"),COUNT(B22:D22)=3),B22*C22*D22,"Insufficient Data")) -> Insufficient Data | F22: To confirm | G22: Admin only; no hosting, support or system internet | I22: Use incremental cash spending; avoid printing / toner overlap.
A23: Reporting / communication | E23: =IF(OR(F23="Bundled",F23="Not applicable"),0,IF(AND(OR(F23="Estimated",F23="Confirmed"),COUNT(B23:D23)=3),B23*C23*D23,"Insufficient Data")) -> Insufficient Data | F23: To confirm | G23: Admin only; no hosting, support or system internet | I23: Use incremental cash spending; avoid printing / toner overlap.
A24: Other attributable admin cash costs | E24: =IF(OR(F24="Bundled",F24="Not applicable"),0,IF(AND(OR(F24="Estimated",F24="Confirmed"),COUNT(B24:D24)=3),B24*C24*D24,"Insufficient Data")) -> Insufficient Data | F24: To confirm | G24: Admin only; no hosting, support or system internet | I24: Use incremental cash spending; avoid printing / toner overlap.
A26: Total annual supplies | E26: =IF(COUNT(E17,E18,E19,E20,E21)=5,SUM(E17,E18,E19,E20,E21),"Insufficient Data") -> Insufficient Data
A27: Other annual admin cash costs | E27: =IF(COUNT(E22,E23,E24)=3,SUM(E22,E23,E24),"Insufficient Data") -> Insufficient Data
A28: Annual admin cash cost | E28: =IF(COUNT(E26,E27)=2,SUM(E26,E27),"Insufficient Data") -> Insufficient Data
A30: C. COST VIEW AND FINANCIAL BOUNDARY
A31: Admin cash + allocated labour | E31: =IF(COUNT(E28,G13)=2,SUM(E28,G13),"Insufficient Data") -> Insufficient Data
A32: Recurring system cost (reference only) | E32: ='Recurring Costs'!E16 -> Insufficient Data
A33: Full proposed cash cost | E33: =IF(COUNT(E28,E32)=2,SUM(E28,E32),"Insufficient Data") -> Insufficient Data
A35: Financial Analysis starts with existing minus proposed admin cash, then subtracts recurring system cost once. Row 33 is a reference comparison, not another model expense.
A38: Treatments: Estimated / Confirmed need numeric inputs; Bundled / Not applicable equal an explicit zero; To confirm remains Insufficient Data. Record the supporting basis. Enter zero only after confirming it.

Sheet Tangible Benefits Worksheet
A1: BREAKDOWN OF TANGIBLE BENEFIT WORKSHEET
A2: Cash savings, released staff capacity and potential equipment exposure are separate measures. Positive savings are not presumed.
A3: Blue cells: editable inputs | Gray: supplied data / fixed scope | Green text: formulas | Blank: unknown, never a verified zero
A5: A. SUPPLIES COST REDUCTION
A6: Supply | B6: Existing annual (₱) | C6: Proposed annual (₱) | D6: Reduction (₱) | E6: Classification | F6: Evidence
A7: Paper | B7: ='Existing System Operating Costs'!E17 -> Insufficient Data | C7: ='Proposed System Operating Costs'!E17 -> Insufficient Data | D7: =IF(COUNT(B7,C7)=2,B7-C7,"Insufficient Data") -> Insufficient Data | E7: Potential cash saving; receipts / budget and post-pilot spending required.
A8: Printing / copy service (excludes ink) | B8: ='Existing System Operating Costs'!E18 -> Insufficient Data | C8: ='Proposed System Operating Costs'!E18 -> Insufficient Data | D8: =IF(COUNT(B8,C8)=2,B8-C8,"Insufficient Data") -> Insufficient Data | E8: Potential cash saving; receipts / budget and post-pilot spending required.
A9: Ink / toner (excludes copy-service charge) | B9: ='Existing System Operating Costs'!E19 -> Insufficient Data | C9: ='Proposed System Operating Costs'!E19 -> Insufficient Data | D9: =IF(COUNT(B9,C9)=2,B9-C9,"Insufficient Data") -> Insufficient Data | E9: Potential cash saving; receipts / budget and post-pilot spending required.
A10: Recordkeeping materials | B10: ='Existing System Operating Costs'!E20 -> Insufficient Data | C10: ='Proposed System Operating Costs'!E20 -> Insufficient Data | D10: =IF(COUNT(B10,C10)=2,B10-C10,"Insufficient Data") -> Insufficient Data | E10: Potential cash saving; receipts / budget and post-pilot spending required.
A11: Other office supplies | B11: ='Existing System Operating Costs'!E21 -> Insufficient Data | C11: ='Proposed System Operating Costs'!E21 -> Insufficient Data | D11: =IF(COUNT(B11,C11)=2,B11-C11,"Insufficient Data") -> Insufficient Data | E11: Potential cash saving; receipts / budget and post-pilot spending required.
A12: ANNUAL SUPPLIES REDUCTION | D12: =IF(COUNT(D7,D8,D9,D10,D11)=5,SUM(D7,D8,D9,D10,D11),"Insufficient Data") -> Insufficient Data
A14: B. LABOUR AND PRODUCTIVITY BENEFITS
A15: Activity | B15: Existing person-hours | C15: Proposed person-hours | D15: Annual hours saved | E15: Rate (₱ / hour) | F15: Productivity value (₱) | G15: Cash realization share | H15: Payroll cash saving (₱) | I15: Retained capacity (₱) | J15: Basis / evidence
A16: Inventory monitoring / updates | B16: ='Existing System Operating Costs'!F7 -> Insufficient Data | C16: ='Proposed System Operating Costs'!F7 -> Insufficient Data | D16: =IF(COUNT(B16,C16)=2,B16-C16,"Insufficient Data") -> Insufficient Data | E16: =IF(ISNUMBER('Existing System Operating Costs'!E7),'Existing System Operating Costs'!E7,"") | F16: =IF(COUNT(D16:E16)=2,D16*E16,"Insufficient Data") -> Insufficient Data | G16: 0 | H16: =IF(G16=0,0,IF(COUNT(F16,G16)=2,F16*G16,"Insufficient Data")) -> 0 | I16: =IF(COUNT(F16,H16)=2,F16-H16,"Insufficient Data") -> Insufficient Data | J16: 0% credits no payroll saving. A higher share requires a documented overtime, contract or payroll reduction.
A17: Manual report preparation | B17: ='Existing System Operating Costs'!F8 -> Insufficient Data | C17: ='Proposed System Operating Costs'!F8 -> Insufficient Data | D17: =IF(COUNT(B17,C17)=2,B17-C17,"Insufficient Data") -> Insufficient Data | E17: =IF(ISNUMBER('Existing System Operating Costs'!E8),'Existing System Operating Costs'!E8,"") | F17: =IF(COUNT(D17:E17)=2,D17*E17,"Insufficient Data") -> Insufficient Data | G17: 0 | H17: =IF(G17=0,0,IF(COUNT(F17,G17)=2,F17*G17,"Insufficient Data")) -> 0 | I17: =IF(COUNT(F17,H17)=2,F17-H17,"Insufficient Data") -> Insufficient Data | J17: 0% credits no payroll saving. A higher share requires a documented overtime, contract or payroll reduction.
A18: Inventory reconciliation | B18: ='Existing System Operating Costs'!F9 -> Insufficient Data | C18: ='Proposed System Operating Costs'!F9 -> Insufficient Data | D18: =IF(COUNT(B18,C18)=2,B18-C18,"Insufficient Data") -> Insufficient Data | E18: =IF(ISNUMBER('Existing System Operating Costs'!E9),'Existing System Operating Costs'!E9,"") | F18: =IF(COUNT(D18:E18)=2,D18*E18,"Insufficient Data") -> Insufficient Data | G18: 0 | H18: =IF(G18=0,0,IF(COUNT(F18,G18)=2,F18*G18,"Insufficient Data")) -> 0 | I18: =IF(COUNT(F18,H18)=2,F18-H18,"Insufficient Data") -> Insufficient Data | J18: 0% credits no payroll saving. A higher share requires a documented overtime, contract or payroll reduction.
A19: Equipment accountability follow-ups | B19: ='Existing System Operating Costs'!F10 -> Insufficient Data | C19: ='Proposed System Operating Costs'!F10 -> Insufficient Data | D19: =IF(COUNT(B19,C19)=2,B19-C19,"Insufficient Data") -> Insufficient Data | E19: =IF(ISNUMBER('Existing System Operating Costs'!E10),'Existing System Operating Costs'!E10,"") | F19: =IF(COUNT(D19:E19)=2,D19*E19,"Insufficient Data") -> Insufficient Data | G19: 0 | H19: =IF(G19=0,0,IF(COUNT(F19,G19)=2,F19*G19,"Insufficient Data")) -> 0 | I19: =IF(COUNT(F19,H19)=2,F19-H19,"Insufficient Data") -> Insufficient Data | J19: 0% credits no payroll saving. A higher share requires a documented overtime, contract or payroll reduction.
A21: Total annual hours saved | D21: =IF(COUNT(D16,D17,D18,D19)=4,SUM(D16,D17,D18,D19),"Insufficient Data") -> Insufficient Data
A22: Total productivity value | F22: =IF(COUNT(F16,F17,F18,F19)=4,SUM(F16,F17,F18,F19),"Insufficient Data") -> Insufficient Data
A23: Credited annual payroll cash savings | H23: =IF(COUNT(H16,H17,H18,H19)=4,SUM(H16,H17,H18,H19),"Insufficient Data") -> 0
A24: Retained capacity value (excluded from cash ROI) | I24: =IF(COUNT(I16,I17,I18,I19)=4,SUM(I16,I17,I18,I19),"Insufficient Data") -> Insufficient Data
A26: C. EQUIPMENT ACCOUNTABILITY / COST AVOIDANCE
A27: Benefit / measure | B27: Observed units | C27: Claim input (₱ / year) | D27: Include in cash model? | E27: Credited amount (₱) | F27: Evidence / boundary
A28: Unreconciled inventory exposure | B28: ='Inventory Baseline'!E34 -> 463 | C28: ='Inventory Baseline'!I34 -> Unverified | D28: Never automatic | E28: 0 | F28: Stock-value exposure, not a yearly benefit. Unit replacement prices and physical status unverified.
A29: Avoided confirmed loss / replacement | D29: Exclude | E29: =IF(D29="Exclude",0,IF(ISNUMBER(C29),C29,"Insufficient Data")) -> 0 | F29: Annual attributable saving needs approved evidence, a repeatable baseline and a distinct purchase / loss event. The same event cannot be credited twice.
A30: Avoided duplicate procurement | D30: Exclude | E30: =IF(D30="Exclude",0,IF(ISNUMBER(C30),C30,"Insufficient Data")) -> 0 | F30: Annual attributable saving needs approved evidence, a repeatable baseline and a distinct purchase / loss event. The same event cannot be credited twice.
A32: Equipment benefits credited to cash model | E32: =IF(COUNT(E29,E30)=2,SUM(E29,E30),"Insufficient Data") -> 0
A34: Both equipment benefit lines are excluded by default. Blank claims remain unverified. A one-time recovery of historical items must not be entered as a repeating annual saving. No assumed recovery rate is applied to 463 units.
A36: D. TOTAL ANNUAL TANGIBLE BENEFITS
A37: Supplies cash reduction | E37: =D12 -> Insufficient Data
A38: Other admin cash reduction | E38: =IF(COUNT('Existing System Operating Costs'!E27,'Proposed System Operating Costs'!E27)=2,'Existing System Operating Costs'!E27-'Proposed System Operating Costs'!E27,"Insufficient Data") -> Insufficient Data
A39: Payroll cash savings credited | E39: =H23 -> 0
A40: Equipment / procurement savings credited | E40: =E32 -> 0
A42: TOTAL ANNUAL CASH TANGIBLE BENEFITS | E42: =IF(COUNT(E37,E38,E39,E40)=4,SUM(E37,E38,E39,E40),"Insufficient Data") -> Insufficient Data
A43: Released capacity value (noncash) | E43: =I24 -> Insufficient Data
A44: Cash + retained productivity value | E44: =IF(COUNT(E42,E43)=2,SUM(E42,E43),"Insufficient Data") -> Insufficient Data
A46: Cash ROI uses row 42 only. Productivity-inclusive appraisal uses cash plus retained capacity (row 44), which is labelled separately and is not cash flow. Financial Analysis deducts recurring system cost once.
A48: Annual person-hours = hours/person/event × staff × events/year. Annual hours saved = existing annual person-hours − proposed annual person-hours. With equal staff and workload this equals hours saved per activity × frequency.

Sheet Intangible Benefits
A1: INTANGIBLE BENEFITS
A2: Qualitative benefits tied to reviewed features. Each needs a pilot measure; no monetary amount is assigned.
A3: Blue cells: editable inputs | Gray: supplied data / fixed scope | Green text: formulas | Blank: unknown, never a verified zero
A6: Benefit | B6: Supporting implemented feature | C6: Evidence | D6: Proposed performance indicator | E6: Limitation / condition
A7: Equipment accountability | B7: Named holder, reservation and inspected receipt associate an asset with an accountable person. | C7: R4–R6, R10 | D7: Share of held records with a named active custodian. | E7: Needs timely, truthful handover entry; no automatic physical recovery.
A8: Visibility of assignments | B8: Equipment profiles and project / personal lists expose recorded holder, quantity and location. | C8: R4–R6 | D8: Time to identify recorded holder and site. | E8: Recorded state still requires a physical check.
A9: Record accuracy | B9: Eligibility verification and condition capture reduce inconsistent handovers. | C9: R5, R6, R10 | D9: Record-to-count variance and correction rate. | E9: Actual server migrations and role controls must match reviewed code.
A10: Faster equipment information | B10: Search and filtered inventory views reduce repeated manual lookup. | C10: R4, R7 | D10: Median lookup time in matched pilot tasks. | E10: No measured speed improvement supplied.
A11: Management decisions | B11: Current inventory and movement reports can inform allocation and purchasing review. | C11: R7, R11 | D11: Percentage of purchase decisions checked against available inventory. | E11: No automated procurement optimization or guaranteed savings claimed.
A12: Fewer reporting errors | B12: Report output reuses recorded fields and PDF export instead of retyping a separate summary. | C12: R7, R11 | D12: Report corrections per cycle. | E12: Input errors and incomplete field reports remain possible.
A13: Inventory transparency | B13: Current state is separated from saved historical observations. | C13: R7, R8 | D13: Coverage of scheduled snapshots and reported exceptions. | E13: No historical reconstruction; scheduler setup must be confirmed.
A14: Stronger audit trails | B14: Saved movement actions, inspection notes and recovery actions support traceability. | C14: R5, R6, R11 | D14: Share of sampled handovers with complete movement / receipt evidence. | E14: Movement history is not proof of physical count or a full financial audit.
A15: Management oversight | B15: Role routes, missing / repair views and notifications expose unresolved work. | C15: R6, R8, R9 | D15: Age of unresolved discrepancy cases and overdue actions. | E15: Notifications and scheduling depend on deployed services and user follow-through.
A18: Source review establishes capability, not measured business performance or confirmed production deployment. Demo records and seeded materials do not establish company inventory or financial facts.
A20: Prioritize physical verification of the 3 flagged categories and a matched workload pilot. Do not promise automatic recovery, theft prevention, partial equipment-record receipt or unattended historical reconstruction.

Sheet Financial Analysis
A1: THREE-YEAR FINANCIAL ANALYSIS
A2: Primary model: incremental cash savings. Supplemental economic result adds retained staff capacity. All outputs remain conditional on supplied inputs.
A3: Blue cells: editable inputs | Gray: supplied data / fixed scope | Green text: formulas | Blank: unknown, never a verified zero
A5: Analysis horizon (fixed projection) | B5: 3
A6: Annual discount rate (planning convention) | B6: ='Assumptions and References'!B9 -> 0.08
A8: Year-specific controls | B8: Year 1 | C8: Year 2 | D8: Year 3 | F8: Basis / scope
A9: Cash benefit realization multiplier | B9: 1 | C9: 1 | D9: 1 | F9: 100% = constant annual scenario, not a measured adoption or inflation forecast.
A10: Recurring cost multiplier | B10: 1 | C10: 1 | D10: 1 | F10: 100% = constant annual scenario, not a measured adoption or inflation forecast.
A12: A. LINKED BASE-YEAR INPUTS
A13: Total one-time investment | B13: ='One-Time Development Cost'!E33 -> Insufficient Data
A14: Annual recurring system cost | B14: ='Recurring Costs'!E16 -> Insufficient Data
A15: Annual cash tangible benefits | B15: ='Tangible Benefits Worksheet'!E42 -> Insufficient Data
A16: Annual retained productivity value (noncash) | B16: ='Tangible Benefits Worksheet'!E43 -> Insufficient Data
A17: Annual net cash benefit | B17: =IF(COUNT(B15,B14)=2,B15-B14,"Insufficient Data") -> Insufficient Data
A19: B. CASH FLOW AT YEAR END; INITIAL INVESTMENT AT YEAR 0
A20: Cash flow measure | B20: Year 0 | C20: Year 1 | D20: Year 2 | E20: Year 3 | F20: Interpretation
A21: Annual tangible cash benefits | B21: 0 | C21: =IF(ISNUMBER($B$15),$B$15*B9,"Insufficient Data") -> Insufficient Data | D21: =IF(ISNUMBER($B$15),$B$15*C9,"Insufficient Data") -> Insufficient Data | E21: =IF(ISNUMBER($B$15),$B$15*D9,"Insufficient Data") -> Insufficient Data
A22: Recurring system cash cost | B22: 0 | C22: =IF(ISNUMBER($B$14),$B$14*B10,"Insufficient Data") -> Insufficient Data | D22: =IF(ISNUMBER($B$14),$B$14*C10,"Insufficient Data") -> Insufficient Data | E22: =IF(ISNUMBER($B$14),$B$14*D10,"Insufficient Data") -> Insufficient Data
A23: One-time investment | B23: =B13 -> Insufficient Data | C23: 0 | D23: 0 | E23: 0
A24: Net cash flow | B24: =IF(COUNT(B21:B23)=3,B21-B22-B23,"Insufficient Data") -> Insufficient Data | C24: =IF(COUNT(C21:C23)=3,C21-C22-C23,"Insufficient Data") -> Insufficient Data | D24: =IF(COUNT(D21:D23)=3,D21-D22-D23,"Insufficient Data") -> Insufficient Data | E24: =IF(COUNT(E21:E23)=3,E21-E22-E23,"Insufficient Data") -> Insufficient Data
A25: Cumulative cash flow | B25: =B24 -> Insufficient Data | C25: =IF(COUNT(B25,C24)=2,SUM(B25,C24),"Insufficient Data") -> Insufficient Data | D25: =IF(COUNT(C25,D24)=2,SUM(C25,D24),"Insufficient Data") -> Insufficient Data | E25: =IF(COUNT(D25,E24)=2,SUM(D25,E24),"Insufficient Data") -> Insufficient Data
A26: Discount factor | B26: =1/(1+$B$6)^0 -> 1 | C26: =1/(1+$B$6)^1 -> 0.92592593 | D26: =1/(1+$B$6)^2 -> 0.85733882 | E26: =1/(1+$B$6)^3 -> 0.79383224
A27: Present value of net cash flow | B27: =IF(ISNUMBER(B24),B24*B26,"Insufficient Data") -> Insufficient Data | C27: =IF(ISNUMBER(C24),C24*C26,"Insufficient Data") -> Insufficient Data | D27: =IF(ISNUMBER(D24),D24*D26,"Insufficient Data") -> Insufficient Data | E27: =IF(ISNUMBER(E24),E24*E26,"Insufficient Data") -> Insufficient Data
A29: Core financial results include no automatic value for 463 gaps. Benefits and recurring costs are linked once. Negative savings remain negative.
A31: C. CASH INVESTMENT RESULTS
A32: Three-year undiscounted cash benefits | B32: =IF(COUNT(C21,D21,E21)=3,SUM(C21,D21,E21),"Insufficient Data") -> Insufficient Data
A33: Three-year total cost incl. initial investment | B33: =IF(COUNT(B13,C22,D22,E22)=4,SUM(B13,C22,D22,E22),"Insufficient Data") -> Insufficient Data
A34: Three-year ROI | B34: =IF(COUNT(B13,C24:E24)=4,IF(B13>0,(SUM(C24:E24)-B13)/B13,"Not applicable: zero investment"),"Insufficient Data") -> Insufficient Data
A35: Discounted benefit-cost ratio | B35: =IF(COUNT(B13,C21:E22)=7,IF(B13+C22*C26+D22*D26+E22*E26>0,(C21*C26+D21*D26+E21*E26)/(B13+C22*C26+D22*D26+E22*E26),"Not applicable: zero cost"),"Insufficient Data") -> Insufficient Data
A36: Cash NPV | B36: =IF(COUNT(B24:E24)=4,SUM(B27:E27),"Insufficient Data") -> Insufficient Data
A37: Payback period (years) | B37: =IF(COUNT(B13,C24:E24)=4,IF(B13=0,0,IF(AND(C24=D24,D24=E24,C24>0),IF(B13/C24<=3,B13/C24,"Not recovered in 3 years"),IF(C25>=0,B13/C24,IF(D25>=0,1-C25/D24,IF(E25>=0,2-D25/E24,"Not recovered in 3 years"))))),"Insufficient Data") -> Insufficient Data
A38: Year 3 cumulative net cash result | B38: =E25 -> Insufficient Data
A39: Required level annual cash benefit (zero NPV) | B39: =IF(COUNT(B13,B14)=2,B14+B13/SUM(C26:E26),"Insufficient Data") -> Insufficient Data
A40: Required level annual cash benefit (3-year payback) | B40: =IF(COUNT(B13,B14)=2,B14+B13/3,"Insufficient Data") -> Insufficient Data
A42: ROI = (sum of operating net benefits in Years 1–3 − initial investment) / initial investment. Discounted BCR = PV cash benefits / (initial investment + PV recurring costs). NPV discounts year-end flows.
A44: Payback assumes net benefits accrue evenly within each year. Constant positive flow uses investment / annual net benefit; variable flow uses the first cumulative crossing. No recovery within the horizon is reported explicitly.
A46: D. SUPPLEMENTAL ECONOMIC VIEW — NOT CASH FLOW
A47: Productivity-inclusive NPV | B47: =IF(COUNT(B36,B16)=2,B36+B16*(B9*C26+C9*D26+D9*E26),"Insufficient Data") -> Insufficient Data
A49: Economic NPV adds retained capacity after excluding any portion already credited to payroll cash savings. It is not cash ROI. No terminal resale value, tax effect, price escalation, financing charge or confirmed equipment saving is assumed.

Sheet Assumptions and References
A1: ASSUMPTIONS AND REFERENCES
A2: Read this sheet first. Confirmed inventory facts are separated from estimates, unknowns and modelling conventions.
A3: Blue cells: editable inputs | Gray: supplied data / fixed scope | Green text: formulas | Blank: unknown, never a verified zero
A5: Item | B5: Value / input | C5: Evidence class | D5: Basis / limitation
A6: Prepared date | B6: 24 October 2026 | C6: Document date | D6: Asia/Manila; source worksheet date not supplied.
A7: Currency | B7: PHP / Philippine Peso | C7: Display convention | D7: No foreign exchange assumption needed; request local quotations.
A8: Development duration (calendar months) | B8: 3 | C8: Editable planning assumption | D8: Academic three-month planning window only; not actual elapsed development effort. Person-months must be supplied separately.
A9: Annual discount rate | B9: 0.08 | C9: Editable modelling convention | D9: 8% is an illustrative sensitivity input, not a company hurdle rate or market quote. Replace with an approved rate.
A10: Analysis horizon | B10: 3 | C10: Fixed model scope | D10: Years 1–3 plus Year 0. Set year multipliers in Financial Analysis; no escalation assumed.
A11: Financial inputs at preparation | B11: Not supplied | C11: Unknown | D11: No rates, supplier quotes, measured task times, approved cash reductions or confirmed loss history supplied.
A12: Recorded equipment units | B12: 758 | C12: Supplied quantity | D12: 26 populated categories. Mixed units are not equivalent economic assets.
A13: Reported missing / no-report units | B13: 463 | C13: Supplied reconciliation gap | D13: Three supplied gaps: 19 + 75 + 369. No conclusion of theft, physical loss or automatic recovery.
A14: Required units in flagged categories | B14: 852 | C14: Supplied partial coverage | D14: 42 + 300 + 510. Requirements for the remaining 23 categories were not supplied.
A15: Labour rates and task times | B15: Not supplied | C15: Unknown | D15: Use timesheets and approved pay / contractor rates. No employee headcount reduction assumed.
A16: Hosting, database and storage | B16: Not supplied | C16: Unknown | D16: Supabase-backed code does not identify the paid plan, actual usage, free capacity or incremental provider bill.
A17: Equipment unit replacement prices | B17: Not supplied | C17: Unknown | D17: Blue price/source fields remain blank. Use dated local supplier quotes matching specifications, tax and delivery basis.
A18: Payroll cash realization | B18: 0 | C18: Default model exclusion | D18: 0% of productivity value credited to cash savings until a corresponding cash expense can be shown to decline.
A19: Equipment cost-avoidance credit | B19: 0 | C19: Default model exclusion | D19: Equipment replacement and duplicate-procurement claims excluded until supported by disjoint annual evidence.
A20: Task staffing default | B20: 1 | C20: Editable modelling convention | D20: One person per activity is a placeholder, not actual company staffing. Confirm for both workflows.
A21: Weekly report frequency default | B21: 52 | C21: Editable planning convention | D21: PRODUCT.md specifies a weekly report; 52 cycles assumes one full operating year. Actual reporting calendar remains to confirm.
A22: Billing frequencies | B22: 12 monthly / 1 annual | C22: Editable modelling convention | D22: These are unit conversions only, not actual purchased services. Verify each line.
A23: Cash model boundary | B23: Incremental cash savings | C23: Analysis policy | D23: Admin cash reduction plus evidenced payroll and equipment saving, less recurring system cost once.
A24: Economic model boundary | B24: Cash + retained capacity | C24: Supplemental only | D24: Retained capacity excludes the portion already realized as payroll cash saving.
A25: Existing workflow | B25: Partly inferred | C25: Evidence limitation | D25: Worksheet proves recorded monitoring fields. Collection, follow-up, reconciliation and report activities are analytical workflow assumptions pending staff interview.
A26: Production effectiveness | B26: Not verified | C26: Evidence limitation | D26: Repository supports features; no live database, uptime, scheduler operation or performance benchmark was verified.
A27: Taxes / terminal value / financing | B27: Excluded | C27: Modelling convention | D27: Use consistent gross cash quotes; no tax shield, resale proceeds or financing cost is credited. Three-year constant-price view.
A28: Prior development work | B28: Separate before approval | C28: Decision boundary | D28: Workbook values full development/implementation scope. For a remaining-investment decision, exclude sunk cash already spent and document the revised scope.
A29: Report synchronization | B29: Dated snapshot | C29: Use instruction | D29: Excel formulas update on editing. Word/PDF do not live-link; regenerate/update both reports after financial inputs change.
A32: ID / source | B32: Location / source | C32: Evidence class | D32: Description / limits
A33: R1 | Supplied inventory image | B33: Supplied inventory image | C33: Supplied reference | D33: HAND TOOLS AND OTHERS MONITORING; undated; 26 populated rows. Blank row 27 excluded.
A34: R2 | User-supplied transcription | B34: User-supplied transcription | C34: Supplied reference | D34: Pasted text.txt; supplied quantities cross-checked against R1.
A35: R3 | Academic reference images | B35: Academic reference images | C35: Supplied reference | D35: IT303 Systems Analysis and Design, Unit 2; visible printed page 105 and subsequent benefits worksheet / viewer pages 58–59. Layout only; full bibliographic details not supplied.
